Workbook

Sheet G. Corriente
D3: Producto | E3: Precio | F3: Fecha | G3: Precio | H3: Fecha | I3: Precio | J3: Fecha | K3: Precio | L3: Fecha | M3: Precio | N3: Fecha
D4: G. Corriente | E4: 15590 | F4: 46054 | G4: 15190 | H4: 46058
B6: Día | D6: Inv Inicial | E6: Ventas | F6: Recibos | G6: Inv Teorico | H6: Inv Final | I6: Fluc Dia | J6: Fluc Acum | K6: Fluctuacion ($)
B7: 1 | C7: D | D7: 7703.17 | E7: 4423.23 | F7: =+Facturas!D4+Facturas!D5 -> 0 | G7: =+D7+F7-E7 -> 3279.94 | H7: 3306.41 | I7: =IF(E7=0,0,+H7-G7) -> 26.47 | J7: =+I7 -> 26.47 | K7: =+J7*$E$4 -> 412667.3
B8: 2 | C8: L | D8: =+H7 -> 3306.41 | E8: 2776.75 | F8: =+Facturas!D6+Facturas!D7 -> 5800 | G8: =+D8+F8-E8 -> 6329.66 | H8: 6356.311 | I8: =IF(E8=0,0,+H8-G8) -> 26.651 | J8: =+J7+I8 -> 53.121 | K8: =+J8*$E$4 -> 828156.39
B9: 3 | C9: M | D9: =+H8 -> 6356.311 | E9: 2808.95 | F9: =+Facturas!D8+Facturas!D9 -> 4000 | G9: =+D9+F9-E9 -> 7547.361 | H9: 7608.221 | I9: =IF(E9=0,0,+H9-G9) -> 60.86 | J9: =+J8+I9 -> 113.981 | K9: =+J9*$E$4 -> 1776963.8
B10: 4 | C10: M | D10: =+H9 -> 7608.221 | E10: 2858.38 | F10: =+Facturas!D10+Facturas!D11 -> 2800 | G10: =+D10+F10-E10 -> 7549.841 | H10: 7464.081 | I10: =IF(E10=0,0,+H10-G10) -> -85.76 | J10: =+J9+I10 -> 28.221 | K10: =+J10*$E$4 -> 439965.39
B11: 5 | C11: J | D11: =+H10 -> 7464.081 | E11: 1395.91 | F11: =+Facturas!D12+Facturas!D13 -> 2800 | G11: =+D11+F11-E11 -> 8868.171 | H11: 8778.85 | I11: =IF(E11=0,0,+H11-G11) -> -89.321 | J11: =+J10+I11 -> -61.1 | K11: =+J11*$G$4 -> -928109
B12: 6 | C12: V | D12: =+H11 -> 8778.85 | E12: 3847.01 | F12: =+Facturas!D14+Facturas!D15 -> 4600 | G12: =+D12+F12-E12 -> 9531.84 | H12: 9476.071 | I12: =IF(E12=0,0,+H12-G12) -> -55.769 | J12: =+J11+I12 -> -116.869 | K12: =+J12*$G$4 -> -1775240.1
B13: 7 | C13: S | D13: =+H12 -> 9476.071 | E13: 4825.95 | F13: =+Facturas!D16+Facturas!D17 -> 4600 | G13: =+D13+F13-E13 -> 9250.121 | H13: 9256.63 | I13: =IF(E13=0,0,+H13-G13) -> 6.509 | J13: =+J12+I13 -> -110.36 | K13: =+J13*$G$4 -> -1676368.4
B14: 8 | C14: D | D14: =+H13 -> 9256.63 | E14: 4423.63 | F14: =+Facturas!D18+Facturas!D19 -> 0 | G14: =+D14+F14-E14 -> 4833 | H14: 5037.03 | I14: =IF(E14=0,0,+H14-G14) -> 204.03 | J14: =+J13+I14 -> 93.67 | K14: =+J14*$G$4 -> 1422847.3
B15: 9 | C15: L | D15: =+H14 -> 5037.03 | E15: 3218.93 | F15: =+Facturas!D20+Facturas!D21 -> 4600 | G15: =+D15+F15-E15 -> 6418.1 | H15: 6356.311 | I15: =IF(E15=0,0,+H15-G15) -> -61.789 | J15: =+J14+I15 -> 31.881 | K15: =+J15*$G$4 -> 484272.39
B16: 10 | C16: M | D16: =+H15 -> 6356.311 | E16: 3206.85 | F16: =+Facturas!D22+Facturas!D23 -> 3700 | G16: =+D16+F16-E16 -> 6849.461 | H16: 6818.73 | I16: =IF(E16=0,0,+H16-G16) -> -30.731 | J16: =+J15+I16 -> 1.15 | K16: =+J16*$G$4 -> 17468.5
B17: 11 | C17: M | D17: =+H16 -> 6818.73 | E17: 3318.89 | F17: =+Facturas!D24+Facturas!D25 -> 1800 | G17: =+D17+F17-E17 -> 5299.84 | H17: 5302.771 | I17: =IF(E17=0,0,+H17-G17) -> 2.931 | J17: =+J16+I17 -> 4.081 | K17: =+J17*$G$4 -> 61990.39
B18: 12 | C18: J | D18: =+H17 -> 5302.771 | E18: 3262.23 | F18: =+Facturas!D26+Facturas!D27 -> 4000 | G18: =+D18+F18-E18 -> 6040.541 | H18: 6043.01 | I18: =IF(E18=0,0,+H18-G18) -> 2.469 | J18: =+J17+I18 -> 6.55 | K18: =+J18*$G$4 -> 99494.5
B19: 13 | C19: V | D19: =+H18 -> 6043.01 | E19: 3666.17 | F19: =+Facturas!D28+Facturas!D29 -> 4000 | G19: =+D19+F19-E19 -> 6376.84 | H19: 6804.18 | I19: =IF(E19=0,0,+H19-G19) -> 427.34 | J19: =+J18+I19 -> 433.89 | K19: =+J19*$G$4 -> 6590789.1
B20: 14 | C20: S | D20: =+H19 -> 6804.18 | E20: 5758.98 | F20: =+Facturas!D30+Facturas!D31 -> 7400 | G20: =+D20+F20-E20 -> 8445.2 | H20: 7982.13 | I20: =IF(E20=0,0,+H20-G20) -> -463.07 | J20: =+J19+I20 -> -29.18 | K20: =+J20*$G$4 -> -443244.2
B21: 15 | C21: D | D21: =+H20 -> 7982.13 | E21: 4787.87 | F21: =+Facturas!D32+Facturas!D33 -> 4600 | G21: =+D21+F21-E21 -> 7794.26 | H21: 8118.09 | I21: =IF(E21=0,0,+H21-G21) -> 323.83 | J21: =+J20+I21 -> 294.65 | K21: =+J21*$G$4 -> 4475733.5
B22: 16 | C22: L | D22: =+H21 -> 8118.09 | E22: 3117.04 | F22: =+Facturas!D34+Facturas!D35 -> 0 | G22: =+D22+F22-E22 -> 5001.05 | H22: 4771.391 | I22: =IF(E22=0,0,+H22-G22) -> -229.659 | J22: =+J21+I22 -> 64.991 | K22: =+J22*$G$4 -> 987213.29
B23: 17 | C23: M | D23: =+H22 -> 4771.391 | E23: 3498.07 | F23: =+Facturas!D36+Facturas!D37 -> 7900 | G23: =+D23+F23-E23 -> 9173.321 | H23: 5779.741 | I23: =IF(E23=0,0,+H23-G23) -> -3393.58 | J23: =+J22+I23 -> -3328.589 | K23: =+J23*$G$4 -> -50561267
B24: 18 | C24: M | D24: =+H23 -> 5779.741 | E24: 3360.64 | F24: =+Facturas!D38+Facturas!D39 -> 1800 | G24: =+D24+F24-E24 -> 4219.101 | H24: 7512.351 | I24: =IF(E24=0,0,+H24-G24) -> 3293.25 | J24: =+J23+I24 -> -35.339 | K24: =+J24*$G$4 -> -536799.41
B25: 19 | C25: J | D25: =+H24 -> 7512.351 | E25: 3465.34 | F25: =+Facturas!D40+Facturas!D41 -> 0 | G25: =+D25+F25-E25 -> 4047.011 | H25: 4084.5 | I25: =IF(E25=0,0,+H25-G25) -> 37.489 | J25: =+J24+I25 -> 2.15 | K25: =+J25*$G$4 -> 32658.5
B26: 20 | C26: V | D26: =+H25 -> 4084.5 | E26: 4211.55 | F26: =+Facturas!D42+Facturas!D43 -> 3500 | G26: =+D26+F26-E26 -> 3372.95 | H26: 3357.611 | I26: =IF(E26=0,0,+H26-G26) -> -15.339 | J26: =+J25+I26 -> -13.189 | K26: =+J26*$G$4 -> -200340.91
B27: 21 | C27: S | D27: =+H26 -> 3357.611 | E27: 5393.43 | F27: =+Facturas!D44+Facturas!D45 -> 5800 | G27: =+D27+F27-E27 -> 3764.181 | H27: 3822.94 | I27: =IF(E27=0,0,+H27-G27) -> 58.759 | J27: =+J26+I27 -> 45.57 | K27: =+J27*$G$4 -> 692208.3
B28: 22 | C28: D | D28: =+H27 -> 3822.94 | E28: 4222.01 | F28: =+Facturas!D46+Facturas!D47 -> 5800 | G28: =+D28+F28-E28 -> 5400.93 | H28: 5355.88 | I28: =IF(E28=0,0,+H28-G28) -> -45.05 | J28: =+J27+I28 -> 0.52 | K28: =+J28*$G$4 -> 7898.8
B29: 23 | C29: L | D29: =+H28 -> 5355.88 | E29: 3304.58 | F29: =+Facturas!D48+Facturas!D49 -> 3500 | G29: =+D29+F29-E29 -> 5551.3 | H29: 5568.11 | I29: =IF(E29=0,0,+H29-G29) -> 16.81 | J29: =+J28+I29 -> 17.33 | K29: =+J29*$G$4 -> 263242.7
B30: 24 | C30: M | D30: =+H29 -> 5568.11 | E30: 3183.75 | F30: =+Facturas!D50+Facturas!D51 -> 4000 | G30: =+D30+F30-E30 -> 6384.36 | H30: 6356.311 | I30: =IF(E30=0,0,+H30-G30) -> -28.049 | J30: =+J29+I30 -> -10.719 | K30: =+J30*$G$4 -> -162821.61
B31: 25 | C31: M | D31: =+H30 -> 6356.311 | E31: 3467.68 | F31: =+Facturas!D52+Facturas!D53 -> 2700 | G31: =+D31+F31-E31 -> 5588.631 | H31: 5668.701 | I31: =IF(E31=0,0,+H31-G31) -> 80.07 | J31: =+J30+I31 -> 69.351 | K31: =+J31*$G$4 -> 1053441.7
B32: 26 | C32: J | D32: =+H31 -> 5668.701 | E32: 3178.01 | F32: =+Facturas!D54+Facturas!D55 -> 2700 | G32: =+D32+F32-E32 -> 5190.691 | H32: 5090.181 | I32: =IF(E32=0,0,+H32-G32) -> -100.51 | J32: =+J31+I32 -> -31.159 | K32: =+J32*$G$4 -> -473305.21
B33: 27 | C33: V | D33: =+H32 -> 5090.181 | E33: 4230.98 | F33: =+Facturas!D56+Facturas!D57 -> 8700 | G33: =+D33+F33-E33 -> 9559.201 | H33: 6147.8 | I33: =IF(E33=0,0,+H33-G33) -> -3411.401 | J33: =+J32+I33 -> -3442.56 | K33: =+J33*$G$4 -> -52292486
B34: 28 | C34: S | D34: =+H33 -> 6147.8 | E34: 6102.09 | F34: =+Facturas!D58+Facturas!D59 -> 3500 | G34: =+D34+F34-E34 -> 3545.71 | H34: 6919.96 | I34: =IF(E34=0,0,+H34-G34) -> 3374.25 | J34: =+J33+I34 -> -68.31 | K34: =+J34*$G$4 -> -1037628.9
B35: 29 | C35: D | D35: =+H34 -> 6919.96 | F35: =+Facturas!D60+Facturas!D61 -> 0 | G35: =+D35+F35-E35 -> 6919.96 | I35: =IF(E35=0,0,+H35-G35) -> 0 | J35: =+J34+I35 -> -68.31 | K35: =+J35*$G$4 -> -1037628.9
B36: 30 | C36: L | D36: =+H35 -> 0 | F36: =+Facturas!D62+Facturas!D63 -> 0 | G36: =+D36+F36-E36 -> 0 | I36: =IF(E36=0,0,+H36-G36) -> 0 | J36: =+J35+I36 -> -68.31 | K36: =+J36*$G$4 -> -1037628.9
B37: 31 | C37: M | D37: =+H36 -> 0 | F37: =+Facturas!D64+Facturas!D65 -> 0 | G37: =+D37+F37-E37 -> 0 | I37: =IF(E37=0,0,+H37-G37) -> 0 | J37: =+J36+I37 -> -68.31 | K37: =+J37*$G$4 -> -1037628.9
E38: =SUM(E7:E37) -> 105314.9 | F38: =SUM(F7:F37) -> 104600
D39: PROM. DIA | E39: =+AVERAGEIF(E7:E37,">0",E7:E37) -> 3761.2464 | F39: =+AVERAGEIF(F7:F37,">0",F7:F37) -> 4358.3333
D40: 31 | E40: =+E39*D40 -> 116598.64 | F40: =+E40/Presupuesto!#REF! -> #REF!

Sheet Bioacem
D3: Producto | E3: Precio | F3: Fecha | G3: Precio | H3: Fecha | I3: Precio | J3: Fecha | K3: Precio | L3: Fecha
D4: Bioacem | E4: 10750 | F4: 46043
B6: Día | D6: Inv Inicial | E6: Ventas | F6: Recibos | G6: Inv Teorico | H6: Inv Final | I6: Fluc Dia | J6: Fluc Acum | K6: Venta Fluct ($)
B7: 1 | C7: =+'G. Corriente'!C7 -> D | D7: =9641.241+3010.186 -> 12651.427 | E7: 1255.44 | F7: =+Facturas!G4+Facturas!G5 -> 0 | G7: =+D7+F7-E7 -> 11395.987 | H7: =9499.8+1895.734 -> 11395.534 | I7: =IF(E7=0,0,+H7-G7) -> -0.453 | J7: =+I7 -> -0.453 | K7: =+J7*$E$4 -> -4869.75
B8: 2 | C8: =+'G. Corriente'!C8 -> L | D8: =+H7 -> 11395.534 | E8: 5294.17 | F8: =+Facturas!G6+Facturas!G7 -> 2800 | G8: =+D8+F8-E8 -> 8901.364 | H8: =6388.98+4268 -> 10656.98 | I8: =IF(E8=0,0,+H8-G8) -> 1755.616 | J8: =+J7+I8 -> 1755.163 | K8: =+J8*$E$4 -> 18868002
B9: 3 | C9: =+'G. Corriente'!C9 -> M | D9: =+H8 -> 10656.98 | E9: 5289.52 | F9: =+Facturas!G8+Facturas!G9 -> 4600 | G9: =+D9+F9-E9 -> 9967.46 | H9: 8419 | I9: =IF(E9=0,0,+H9-G9) -> -1548.46 | J9: =+J8+I9 -> 206.703 | K9: =+J9*$E$4 -> 2222057.3
B10: 4 | C10: =+'G. Corriente'!C10 -> M | D10: =+H9 -> 8419 | E10: 5582.65 | F10: =+Facturas!G10+Facturas!G11 -> 5800 | G10: =+D10+F10-E10 -> 8636.35 | H10: =5687.791+2887.646 -> 8575.437 | I10: =IF(E10=0,0,+H10-G10) -> -60.913 | J10: =+J9+I10 -> 145.79 | K10: =+J10*$E$4 -> 1567242.5
B11: 5 | C11: =+'G. Corriente'!C11 -> J | D11: =+H10 -> 8575.437 | E11: 5661.36 | F11: =+Facturas!G12+Facturas!G13 -> 3500 | G11: =+D11+F11-E11 -> 6414.077 | H11: =5951.161+457.326 -> 6408.487 | I11: =IF(E11=0,0,+H11-G11) -> -5.59 | J11: =+J10+I11 -> 140.2 | K11: =+J11*$E$4 -> 1507150
B12: 6 | C12: =+'G. Corriente'!C12 -> V | D12: =+H11 -> 6408.487 | E12: 4443.78 | F12: =+Facturas!G14+Facturas!G15 -> 8700 | G12: =+D12+F12-E12 -> 10664.707 | H12: =7082.96+3327.073 -> 10410.033 | I12: =IF(E12=0,0,+H12-G12) -> -254.674 | J12: =+J11+I12 -> -114.474 | K12: =+J12*$E$4 -> -1230595.5
B13: 7 | C13: =+'G. Corriente'!C13 -> S | D13: =+H12 -> 10410.033 | E13: 4198.96 | F13: =+Facturas!G16+Facturas!G17 -> 3500 | G13: =+D13+F13-E13 -> 9711.073 | H13: =6881.8+3190.855 -> 10072.655 | I13: =IF(E13=0,0,+H13-G13) -> 361.582 | J13: =+J12+I13 -> 247.108 | K13: =+J13*$E$4 -> 2656411
B14: 8 | C14: =+'G. Corriente'!C14 -> D | D14: =+H13 -> 10072.655 | E14: 1773.03 | F14: =+Facturas!G18+Facturas!G19 -> 0 | G14: =+D14+F14-E14 -> 8299.625 | H14: =5845.971+2665.554 -> 8511.525 | I14: =IF(E14=0,0,+H14-G14) -> 211.9 | J14: =+J13+I14 -> 459.008 | K14: =+J14*$E$4 -> 4934336
B15: 9 | C15: =+'G. Corriente'!C15 -> L | D15: =+H14 -> 8511.525 | E15: 4911.96 | F15: =+Facturas!G20+Facturas!G21 -> 4000 | G15: =+D15+F15-E15 -> 7599.565 | H15: =5793.291+1629.61 -> 7422.901 | I15: =IF(E15=0,0,+H15-G15) -> -176.664 | J15: =+J14+I15 -> 282.344 | K15: =+J15*$E$4 -> 3035198
B16: 10 | C16: =+'G. Corriente'!C16 -> M | D16: =+H15 -> 7422.901 | E16: 5231.89 | F16: =+Facturas!G22+Facturas!G23 -> 5200 | G16: =+D16+F16-E16 -> 7391.011 | H16: =5423.4+1976.789 -> 7400.189 | I16: =IF(E16=0,0,+H16-G16) -> 9.178 | J16: =+J15+I16 -> 291.522 | K16: =+J16*$E$4 -> 3133861.5
B17: 11 | C17: =+'G. Corriente'!C17 -> M | D17: =+H16 -> 7400.189 | E17: 4905.58 | F17: =+Facturas!G24+Facturas!G25 -> 6800 | G17: =+D17+F17-E17 -> 9294.609 | H17: =6368.98+2915.351 -> 9284.331 | I17: =IF(E17=0,0,+H17-G17) -> -10.278 | J17: =+J16+I17 -> 281.244 | K17: =+J17*$E$4 -> 3023373
B18: 12 | C18: =+'G. Corriente'!C18 -> J | D18: =+H17 -> 9284.331 | E18: 5109.38 | F18: =+Facturas!G26+Facturas!G27 -> 4600 | G18: =+D18+F18-E18 -> 8774.951 | H18: =5793.291+3025.937 -> 8819.228 | I18: =IF(E18=0,0,+H18-G18) -> 44.277 | J18: =+J17+I18 -> 325.521 | K18: =+J18*$E$4 -> 3499350.7
B19: 13 | C19: =+'G. Corriente'!C19 -> V | D19: =+H18 -> 8819.228 | E19: 4691.25 | F19: =+Facturas!G28+Facturas!G29 -> 4600 | G19: =+D19+F19-E19 -> 8727.978 | H19: =6212.931+2526.687 -> 8739.618 | I19: =IF(E19=0,0,+H19-G19) -> 11.64 | J19: =+J18+I19 -> 337.161 | K19: =+J19*$E$4 -> 3624480.7
B20: 14 | C20: =+'G. Corriente'!C20 -> S | D20: =+H19 -> 8739.618 | E20: 3150.09 | F20: =+Facturas!G30+Facturas!G31 -> 8000 | G20: =+D20+F20-E20 -> 13589.528 | H20: =8776.371+4739.05 -> 13515.421 | I20: =IF(E20=0,0,+H20-G20) -> -74.107 | J20: =+J19+I20 -> 263.054 | K20: =+J20*$E$4 -> 2827830.5
B21: 15 | C21: =+'G. Corriente'!C21 -> D | D21: =+H20 -> 13515.421 | E21: 1453.16 | F21: =+Facturas!G32+Facturas!G33 -> 4000 | G21: =+D21+F21-E21 -> 16062.261 | H21: =7995.71+4080.061 -> 12075.771 | I21: =IF(E21=0,0,+H21-G21) -> -3986.49 | J21: =+J20+I21 -> -3723.436 | K21: =+J21*$E$4 -> -40026937
B22: 16 | C22: =+'G. Corriente'!C22 -> L | D22: =+H21 -> 12075.771 | E22: 5991.78 | F22: =+Facturas!G34+Facturas!G35 -> 0 | G22: =+D22+F22-E22 -> 6083.991 | H22: =7032.92+3053.512 -> 10086.432 | I22: =IF(E22=0,0,+H22-G22) -> 4002.441 | J22: =+J21+I22 -> 279.005 | K22: =+J22*$E$4 -> 2999303.7
B23: 17 | C23: =+'G. Corriente'!C23 -> M | D23: =+H22 -> 10086.432 | E23: 4767.43 | F23: =+Facturas!G36+Facturas!G37 -> 7000 | G23: =+D23+F23-E23 -> 12319.002 | H23: =7379.451+1473.5 -> 8852.951 | I23: =IF(E23=0,0,+H23-G23) -> -3466.051 | J23: =+J22+I23 -> -3187.046 | K23: =+J23*$E$4 -> -34260744
B24: 18 | C24: =+'G. Corriente'!C24 -> M | D24: =+H23 -> 8852.951 | E24: 5163.7 | F24: =+Facturas!G38+Facturas!G39 -> 6800 | G24: =+D24+F24-E24 -> 10489.251 | H24: =9281.581+4787 -> 14068.581 | I24: =IF(E24=0,0,+H24-G24) -> 3579.33 | J24: =+J23+I24 -> 392.284 | K24: =+J24*$E$4 -> 4217053
B25: 19 | C25: =+'G. Corriente'!C25 -> J | D25: =+H24 -> 14068.581 | E25: 4795.83 | F25: =+Facturas!G40+Facturas!G41 -> 0 | G25: =+D25+F25-E25 -> 9272.751 | H25: =5423.4+3854.757 -> 9278.157 | I25: =IF(E25=0,0,+H25-G25) -> 5.406 | J25: =+J24+I25 -> 397.69 | K25: =+J25*$E$4 -> 4275167.5
B26: 20 | C26: =+'G. Corriente'!C26 -> V | D26: =+H25 -> 9278.157 | E26: 5219.64 | F26: =+Facturas!G42+Facturas!G43 -> 6300 | G26: =+D26+F26-E26 -> 10358.517 | H26: =6626.98+3803.535 -> 10430.515 | I26: =IF(E26=0,0,+H26-G26) -> 71.998 | J26: =+J25+I26 -> 469.688 | K26: =+J26*$E$4 -> 5049146
B27: 21 | C27: =+'G. Corriente'!C27 -> S | D27: =+H26 -> 10430.515 | E27: 2986.4 | F27: =+Facturas!G44+Facturas!G45 -> 2800 | G27: =+D27+F27-E27 -> 10244.115 | H27: =7281.371+2887.646 -> 10169.017 | I27: =IF(E27=0,0,+H27-G27) -> -75.098 | J27: =+J26+I27 -> 394.59 | K27: =+J27*$E$4 -> 4241842.5
B28: 22 | C28: =+'G. Corriente'!C28 -> D | D28: =+H27 -> 10169.017 | E28: 1422.48 | F28: =+Facturas!G46+Facturas!G47 -> 2800 | G28: =+D28+F28-E28 -> 11546.537 | H28: =9463.241+2112.907 -> 11576.148 | I28: =IF(E28=0,0,+H28-G28) -> 29.611 | J28: =+J27+I28 -> 424.201 | K28: =+J28*$E$4 -> 4560160.7
B29: 23 | C29: =+'G. Corriente'!C29 -> L | D29: =+H28 -> 11576.148 | E29: 5211.99 | F29: =+Facturas!G48+Facturas!G49 -> 2800 | G29: =+D29+F29-E29 -> 9164.158 | H29: =6212.931+2915.351 -> 9128.282 | I29: =IF(E29=0,0,+H29-G29) -> -35.876 | J29: =+J28+I29 -> 388.325 | K29: =+J29*$E$4 -> 4174493.7
B30: 24 | C30: =+'G. Corriente'!C30 -> M | D30: =+H29 -> 9128.282 | E30: 4989.73 | F30: =+Facturas!G50+Facturas!G51 -> 4600 | G30: =+D30+F30-E30 -> 8738.552 | H30: =7949.73+771.813 -> 8721.543 | I30: =IF(E30=0,0,+H30-G30) -> -17.009 | J30: =+J29+I30 -> 371.316 | K30: =+J30*$E$4 -> 3991647
B31: 25 | C31: =+'G. Corriente'!C31 -> M | D31: =+H30 -> 8721.543 | E31: 5517.01 | F31: =+Facturas!G52+Facturas!G53 -> 5800 | G31: =+D31+F31-E31 -> 9004.533 | H31: =4840.701+4272.59 -> 9113.291 | I31: =IF(E31=0,0,+H31-G31) -> 108.758 | J31: =+J30+I31 -> 480.074 | K31: =+J31*$E$4 -> 5160795.5
B32: 26 | C32: =+'G. Corriente'!C32 -> J | D32: =+H31 -> 9113.291 | E32: 4652.25 | F32: =+Facturas!G54+Facturas!G55 -> 4000 | G32: =+D32+F32-E32 -> 8461.041 | H32: =4155.88+4248.942 -> 8404.822 | I32: =IF(E32=0,0,+H32-G32) -> -56.219 | J32: =+J31+I32 -> 423.855 | K32: =+J32*$E$4 -> 4556441.2
B33: 27 | C33: =+'G. Corriente'!C33 -> V | D33: =+H32 -> 8404.822 | E33: 5105.15 | F33: =+Facturas!G56+Facturas!G57 -> 11600 | G33: =+D33+F33-E33 -> 14899.672 | H33: =5529.241+3136.036 -> 8665.277 | I33: =IF(E33=0,0,+H33-G33) -> -6234.395 | J33: =+J32+I33 -> -5810.54 | K33: =+J33*$E$4 -> -62463305
B34: 28 | C34: =+'G. Corriente'!C34 -> S | D34: =+H33 -> 8665.277 | E34: 2964.72 | F34: =+Facturas!G58+Facturas!G59 -> 2800 | G34: =+D34+F34-E34 -> 8500.557 | H34: =9886+4906 -> 14792 | I34: =IF(E34=0,0,+H34-G34) -> 6291.443 | J34: =+J33+I34 -> 480.903 | K34: =+J34*$E$4 -> 5169707.2
B35: 29 | C35: =+'G. Corriente'!C35 -> D | D35: =+H34 -> 14792 | F35: =+Facturas!G60+Facturas!G61 -> 0 | G35: =+D35+F35-E35 -> 14792 | I35: =IF(E35=0,0,+H35-G35) -> 0 | J35: =+J34+I35 -> 480.903 | K35: =+J35*$E$4 -> 5169707.2
B36: 30 | C36: =+'G. Corriente'!C36 -> L | D36: =+H35 -> 0 | F36: =+Facturas!G62+Facturas!G63 -> 0 | G36: =+D36+F36-E36 -> 0 | I36: =IF(E36=0,0,+H36-G36) -> 0 | J36: =+J35+I36 -> 480.903 | K36: =+J36*$E$4 -> 5169707.2
B37: 31 | C37: =+'G. Corriente'!C37 -> M | D37: =+H36 -> 0 | F37: =+Facturas!G64+Facturas!G65 -> 0 | G37: =+D37+F37-E37 -> 0 | I37: =IF(E37=0,0,+H37-G37) -> 0 | J37: =+J36+I37 -> 480.903 | K37: =+J37*$E$4 -> 5169707.2
E38: =SUM(E7:E37) -> 121740.33 | F38: =SUM(F7:F37) -> 123400
D39: PROM. DIA | E39: =+AVERAGEIF(E7:E37,">0",E7:E37) -> 4347.8689 | F39: =+AVERAGEIF(F7:F37,">0",F7:F37) -> 5141.6667
D40: =+'G. Corriente'!D40 -> 31 | E40: =+D40*E39 -> 134783.94 | F40: =+E40/Presupuesto!#REF! -> #REF!

Sheet G. Extra
D3: Producto | E3: Precio | F3: Fecha | G3: Precio | H3: Fecha | I3: Precio | J3: Fecha
D4: G. Extra | E4: 19770 | F4: 46023 | G4: 18070 | H4: 46060
B6: Día | D6: Inv Inicial | E6: Ventas | F6: Recibos | G6: Inv Teorico | H6: Inv Final | I6: Fluc Dia | J6: Fluc Acum | K6: Venta Total ($)
B7: 1 | C7: =+'G. Corriente'!C7 -> D | D7: 2194.99 | E7: 473.53 | F7: =+Facturas!E4+Facturas!E5 -> 0 | G7: =+D7+F7-E7 -> 1721.46 | H7: 1712.921 | I7: =IF(E7=0,0,+H7-G7) -> -8.539 | J7: =+I7 -> -8.539 | K7: =+J7*$E$4 -> -168816.03
B8: 2 | C8: =+'G. Corriente'!C8 -> L | D8: =+H7 -> 1712.921 | E8: 215.37 | F8: =+Facturas!E6+Facturas!E7 -> 0 | G8: =+D8+F8-E8 -> 1497.551 | H8: 1530 | I8: =IF(E8=0,0,+H8-G8) -> 32.449 | J8: =+I8+J7 -> 23.91 | K8: =+J8*$E$4 -> 472700.7
B9: 3 | C9: =+'G. Corriente'!C9 -> M | D9: =+H8 -> 1530 | E9: 332.29 | F9: =+Facturas!E8+Facturas!E9 -> 0 | G9: =+D9+F9-E9 -> 1197.71 | H9: 1227.75 | I9: =IF(E9=0,0,+H9-G9) -> 30.04 | J9: =+I9+J8 -> 53.95 | K9: =+J9*$E$4 -> 1066591.5
B10: 4 | C10: =+'G. Corriente'!C10 -> M | D10: =+H9 -> 1227.75 | E10: 300.41 | F10: =+Facturas!E10+Facturas!E11 -> 0 | G10: =+D10+F10-E10 -> 927.34 | H10: 844.66 | I10: =IF(E10=0,0,+H10-G10) -> -82.68 | J10: =+I10+J9 -> -28.73 | K10: =+J10*$E$4 -> -567992.1
B11: 5 | C11: =+'G. Corriente'!C11 -> J | D11: =+H10 -> 844.66 | E11: 86.21 | F11: =+Facturas!E12+Facturas!E13 -> 1800 | G11: =+D11+F11-E11 -> 2558.45 | H11: 2524.341 | I11: =IF(E11=0,0,+H11-G11) -> -34.109 | J11: =+I11+J10 -> -62.839 | K11: =+J11*$E$4 -> -1242327
B12: 6 | C12: =+'G. Corriente'!C12 -> V | D12: =+H11 -> 2524.341 | E12: 331.14 | F12: =+Facturas!E14+Facturas!E15 -> 0 | G12: =+D12+F12-E12 -> 2193.201 | H12: 2276.9 | I12: =IF(E12=0,0,+H12-G12) -> 83.699 | J12: =+I12+J11 -> 20.86 | K12: =+J12*$E$4 -> 412402.2
B13: 7 | C13: =+'G. Corriente'!C13 -> S | D13: =+H12 -> 2276.9 | E13: 658.39 | F13: =+Facturas!E16+Facturas!E17 -> 0 | G13: =+D13+F13-E13 -> 1618.51 | H13: 1608.49 | I13: =IF(E13=0,0,+H13-G13) -> -10.02 | J13: =+I13+J12 -> 10.84 | K13: =+J13*$E$4 -> 214306.8
B14: 8 | C14: =+'G. Corriente'!C14 -> D | D14: =+H13 -> 1608.49 | E14: 413.01 | F14: =+Facturas!E18+Facturas!E19 -> 0 | G14: =+D14+F14-E14 -> 1195.48 | H14: 1227.75 | I14: =IF(E14=0,0,+H14-G14) -> 32.27 | J14: =+I14+J13 -> 43.11 | K14: =+J14*$E$4 -> 852284.7
B15: 9 | C15: =+'G. Corriente'!C15 -> L | D15: =+H14 -> 1227.75 | E15: 290.11 | F15: =+Facturas!E20+Facturas!E21 -> 0 | G15: =+D15+F15-E15 -> 937.64 | H15: 961.35 | I15: =IF(E15=0,0,+H15-G15) -> 23.71 | J15: =+I15+J14 -> 66.82 | K15: =+J15*$E$4 -> 1321031.4
B16: 10 | C16: =+'G. Corriente'!C16 -> M | D16: =+H15 -> 961.35 | E16: 289.67 | F16: =+Facturas!E22+Facturas!E23 -> 1500 | G16: =+D16+F16-E16 -> 2171.68 | H16: 2113.46 | I16: =IF(E16=0,0,+H16-G16) -> -58.22 | J16: =+I16+J15 -> 8.6 | K16: =+J16*$E$4 -> 170022
B17: 11 | C17: =+'G. Corriente'!C17 -> M | D17: =+H16 -> 2113.46 | E17: 329.78 | F17: =+Facturas!E24+Facturas!E25 -> 0 | G17: =+D17+F17-E17 -> 1783.68 | H17: 1765.541 | I17: =IF(E17=0,0,+H17-G17) -> -18.139 | J17: =+I17+J16 -> -9.539 | K17: =+J17*$E$4 -> -188586.03
B18: 12 | C18: =+'G. Corriente'!C18 -> J | D18: =+H17 -> 1765.541 | E18: 303.04 | F18: =+Facturas!E26+Facturas!E27 -> 0 | G18: =+D18+F18-E18 -> 1462.501 | H18: 1505.22 | I18: =IF(E18=0,0,+H18-G18) -> 42.719 | J18: =+I18+J17 -> 33.18 | K18: =+J18*$E$4 -> 655968.6
B19: 13 | C19: =+'G. Corriente'!C19 -> V | D19: =+H18 -> 1505.22 | E19: 448.13 | F19: =+Facturas!E28+Facturas!E29 -> 0 | G19: =+D19+F19-E19 -> 1057.09 | H19: 1032.771 | I19: =IF(E19=0,0,+H19-G19) -> -24.319 | J19: =+I19+J18 -> 8.861 | K19: =+J19*$E$4 -> 175181.97
B20: 14 | C20: =+'G. Corriente'!C20 -> S | D20: =+H19 -> 1032.771 | E20: 802.91 | F20: =+Facturas!E30+Facturas!E31 -> 1800 | G20: =+D20+F20-E20 -> 2029.861 | H20: 2059.331 | I20: =IF(E20=0,0,+H20-G20) -> 29.47 | J20: =+I20+J19 -> 38.331 | K20: =+J20*$E$4 -> 757803.87
B21: 15 | C21: =+'G. Corriente'!C21 -> D | D21: =+H20 -> 2059.331 | E21: 454.83 | F21: =+Facturas!E32+Facturas!E33 -> 0 | G21: =+D21+F21-E21 -> 1604.501 | H21: 1582.57 | I21: =IF(E21=0,0,+H21-G21) -> -21.931 | J21: =+I21+J20 -> 16.4 | K21: =+J21*$E$4 -> 324228
B22: 16 | C22: =+'G. Corriente'!C22 -> L | D22: =+H21 -> 1582.57 | E22: 299.92 | F22: =+Facturas!E34+Facturas!E35 -> 0 | G22: =+D22+F22-E22 -> 1282.65 | H22: 1327.48 | I22: =IF(E22=0,0,+H22-G22) -> 44.83 | J22: =+I22+J21 -> 61.23 | K22: =+J22*$E$4 -> 1210517.1
B23: 17 | C23: =+'G. Corriente'!C23 -> M | D23: =+H22 -> 1327.48 | E23: 318.65 | F23: =+Facturas!E36+Facturas!E37 -> 1800 | G23: =+D23+F23-E23 -> 2808.83 | H23: 937.771 | I23: =IF(E23=0,0,+H23-G23) -> -1871.059 | J23: =+I23+J22 -> -1809.829 | K23: =+J23*$E$4 -> -35780319
B24: 18 | C24: =+'G. Corriente'!C24 -> M | D24: =+H23 -> 937.771 | E24: 282.54 | F24: =+Facturas!E38+Facturas!E39 -> 0 | G24: =+D24+F24-E24 -> 655.231 | H24: 2496.75 | I24: =IF(E24=0,0,+H24-G24) -> 1841.519 | J24: =+I24+J23 -> 31.69 | K24: =+J24*$E$4 -> 626511.3
B25: 19 | C25: =+'G. Corriente'!C25 -> J | D25: =+H24 -> 2496.75 | E25: 340.1 | F25: =+Facturas!E40+Facturas!E41 -> 0 | G25: =+D25+F25-E25 -> 2156.65 | H25: 2140.591 | I25: =IF(E25=0,0,+H25-G25) -> -16.059 | J25: =+I25+J24 -> 15.631 | K25: =+J25*$E$4 -> 309024.87
B26: 20 | C26: =+'G. Corriente'!C26 -> V | D26: =+H25 -> 2140.591 | E26: 452.06 | F26: =+Facturas!E42+Facturas!E43 -> 0 | G26: =+D26+F26-E26 -> 1688.531 | H26: 1765.541 | I26: =IF(E26=0,0,+H26-G26) -> 77.01 | J26: =+I26+J25 -> 92.641 | K26: =+J26*$E$4 -> 1831512.6
B27: 21 | C27: =+'G. Corriente'!C27 -> S | D27: =+H26 -> 1765.541 | E27: 754.92 | F27: =+Facturas!E44+Facturas!E45 -> 0 | G27: =+D27+F27-E27 -> 1010.621 | H27: 937.771 | I27: =IF(E27=0,0,+H27-G27) -> -72.85 | J27: =+I27+J26 -> 19.791 | K27: =+J27*$E$4 -> 391268.07
B28: 22 | C28: =+'G. Corriente'!C28 -> D | D28: =+H27 -> 937.771 | E28: 611.25 | F28: =+Facturas!E46+Facturas!E47 -> 0 | G28: =+D28+F28-E28 -> 326.521 | H28: 341.87 | I28: =IF(E28=0,0,+H28-G28) -> 15.349 | J28: =+I28+J27 -> 35.14 | K28: =+J28*$E$4 -> 694717.8
B29: 23 | C29: =+'G. Corriente'!C29 -> L | D29: =+H28 -> 341.87 | E29: 354.5 | F29: =+Facturas!E48+Facturas!E49 -> 1800 | G29: =+D29+F29-E29 -> 1787.37 | H29: 1765.541 | I29: =IF(E29=0,0,+H29-G29) -> -21.829 | J29: =+I29+J28 -> 13.311 | K29: =+J29*$E$4 -> 263158.47
B30: 24 | C30: =+'G. Corriente'!C30 -> M | D30: =+H29 -> 1765.541 | E30: 286.52 | F30: =+Facturas!E50+Facturas!E51 -> 0 | G30: =+D30+F30-E30 -> 1479.021 | H30: 1505.22 | I30: =IF(E30=0,0,+H30-G30) -> 26.199 | J30: =+I30+J29 -> 39.51 | K30: =+J30*$E$4 -> 781112.7
B31: 25 | C31: =+'G. Corriente'!C31 -> M | D31: =+H30 -> 1505.22 | E31: 338.36 | F31: =+Facturas!E52+Facturas!E53 -> 0 | G31: =+D31+F31-E31 -> 1166.86 | H31: 1129.47 | I31: =IF(E31=0,0,+H31-G31) -> -37.39 | J31: =+I31+J30 -> 2.12 | K31: =+J31*$E$4 -> 41912.4
B32: 26 | C32: =+'G. Corriente'!C32 -> J | D32: =+H31 -> 1129.47 | E32: 376.01 | F32: =+Facturas!E54+Facturas!E55 -> 1800 | G32: =+D32+F32-E32 -> 2553.46 | H32: 2551.94 | I32: =IF(E32=0,0,+H32-G32) -> -1.52 | J32: =+I32+J31 -> 0.6 | K32: =+J32*$E$4 -> 11862
B33: 27 | C33: =+'G. Corriente'!C33 -> V | D33: =+H32 -> 2551.94 | E33: 620.1 | F33: =+Facturas!E56+Facturas!E57 -> 0 | G33: =+D33+F33-E33 -> 1931.84 | H33: 1951.69 | I33: =IF(E33=0,0,+H33-G33) -> 19.85 | J33: =+I33+J32 -> 20.45 | K33: =+J33*$E$4 -> 404296.5
B34: 28 | C34: =+'G. Corriente'!C34 -> S | D34: =+H33 -> 1951.69 | E34: 892.73 | F34: =+Facturas!E58+Facturas!E59 -> 1800 | G34: =+D34+F34-E34 -> 2858.96 | H34: 2817.44 | I34: =IF(E34=0,0,+H34-G34) -> -41.52 | J34: =+I34+J33 -> -21.07 | K34: =+J34*$E$4 -> -416553.9
B35: 29 | C35: =+'G. Corriente'!C35 -> D | D35: =+H34 -> 2817.44 | F35: =+Facturas!E60+Facturas!E61 -> 0 | G35: =+D35+F35-E35 -> 2817.44 | I35: =IF(E35=0,0,+H35-G35) -> 0 | J35: =+I35+J34 -> -21.07 | K35: =+J35*$E$4 -> -416553.9
B36: 30 | C36: =+'G. Corriente'!C36 -> L | D36: =+H35 -> 0 | F36: =+Facturas!E62+Facturas!E63 -> 0 | G36: =+D36+F36-E36 -> 0 | I36: =IF(E36=0,0,+H36-G36) -> 0 | J36: =+I36+J35 -> -21.07 | K36: =+J36*$E$4 -> -416553.9
B37: 31 | C37: =+'G. Corriente'!C37 -> M | D37: =+H36 -> 0 | F37: =+Facturas!E64+Facturas!E65 -> 0 | G37: =+D37+F37-E37 -> 0 | I37: =IF(E37=0,0,+H37-G37) -> 0 | J37: =+I37+J36 -> -21.07 | K37: =+J37*$E$4 -> -416553.9
E38: =SUM(E7:E37) -> 11656.48 | F38: =SUM(F7:F37) -> 12300
D39: PROM. DIA | E39: =+AVERAGEIF(E7:E37,">0",E7:E37) -> 416.30286 | F39: =+AVERAGEIF(F7:F37,">0",F7:F37) -> 1757.1429
D40: =+'G. Corriente'!D40 -> 31 | E40: =+E39*D40 -> 12905.389 | F40: =+E40/Presupuesto!#REF! -> #REF!

Sheet Cierre
B2: Día | D2: Vta Corriente | E2: Vta Bioacem | F2: Vta Extra | G2: Vta Total | H2: Vta Gl | I2: # Clientes | J2: Efectivo | L2: Rumbo | N2: Urea Rumbo | P2: Cons Terpel | R2: Mi Emp | T2: Clien Propios | V2: App Terpel | X2: Go Pass | Z2: Datafono | AB2: QR | AD2: Ajustes | AF2: Vive Terpel | AH2: Urea | AJ2: Efectivo Real | AK2: Diferencia | AL2: Diferencia Acum | AM2: Certificacion | AN2: Diferencia | AO2: Diferencia Acum
B3: 1 | C3: =+Bioacem!C7 -> D | D3: =+'G. Corriente'!E7*'G. Corriente'!$E$4 -> 68958156 | E3: =+Bioacem!E7*Bioacem!$E$4 -> 13495980 | F3: =+'G. Extra'!E7*'G. Extra'!$E$4 -> 9361688.1 | G3: =SUM(C3:F3) -> 91815824 | H3: =+Bioacem!E7+'G. Corriente'!E7+'G. Extra'!E7 -> 6152.2 | I3: =660+500+9+15+7+11+4+1 -> 1207 | J3: =+G3-L3-P3-T3-V3-R3-X3-Z3-AB3-AD3-AF3-AH3 -> 34720329 | K3: =IF(J3=0,0,J3/G3) -> 0.37815191 | L3: =1638161-N3 -> 1560241 | M3: =IF(L3=0,0,L3/G3) -> 0.01699316 | N3: 77920 | O3: =IF(N3=0,0,N3/G3) -> 0.00084865546 | Q3: =IF(P3=0,0,P3/G3) -> 0 | R3: 2100334 | S3: =IF(R3=0,0,R3/G3) -> 0.022875512 | T3: 150156 | U3: =IF(T3=0,0,T3/G3) -> 0.0016354044 | W3: =IF(V3=0,0,V3/G3) -> 0 | X3: 237490 | Y3: =IF(X3=0,0,X3/G3) -> 0.0025865912 | Z3: =47132783+5254344 -> 52387127 | AA3: =IF(Z3=0,0,Z3/G3) -> 0.57056752 | AB3: =+'Vtas efectivo'!Z3 -> 605147 | AC3: =IF(AB3=0,0,AB3/G3) -> 0.0065908792 | AE3: =IF(AD3=0,0,AD3/G3) -> 0 | AF3: 55000 | AG3: =IF(AF3=0,0,AF3/G3) -> 0.00059902528 | AH3: =+'Vtas efectivo'!BK3 -> 0 | AI3: =IF(AH3=0,0,AH3/G3) -> 0 | AJ3: 35091000 | AK3: =+J3-AJ3 -> -370671.2 | AL3: =+AK3 -> -370671.2 | AN3: =+AM3-AJ3 -> -35091000 | AO3: =+AN3 -> -35091000
B4: 2 | C4: =+Bioacem!C8 -> L | D4: =+'G. Corriente'!E8*'G. Corriente'!$E$4 -> 43289532 | E4: =+Bioacem!E8*Bioacem!$E$4 -> 56912328 | F4: =+'G. Extra'!E8*'G. Extra'!$E$4 -> 4257864.9 | G4: =SUM(C4:F4) -> 1.0445972e+08 | H4: =+Bioacem!E8+'G. Corriente'!E8+'G. Extra'!E8 -> 8286.29 | I4: =634+429+34+54+40+15+17+2 -> 1225 | J4: =+G4-L4-P4-T4-V4-R4-X4-Z4-AB4-AD4-AF4-AH4 -> 35522187 | K4: =IF(J4=0,0,J4/G4) -> 0.34005629 | L4: =13927767-N4 -> 13845723 | M4: =IF(L4=0,0,L4/G4) -> 0.13254604 | N4: 82044 | O4: =IF(N4=0,0,N4/G4) -> 0.00078541275 | Q4: =IF(P4=0,0,P4/G4) -> 0 | R4: 7037635 | S4: =IF(R4=0,0,R4/G4) -> 0.067371755 | T4: =5365535+'Vtas efectivo'!BJ4 -> 8200671 | U4: =IF(T4=0,0,T4/G4) -> 0.078505577 | W4: =IF(V4=0,0,V4/G4) -> 0 | X4: 237037 | Y4: =IF(X4=0,0,X4/G4) -> 0.0022691712 | Z4: =37532239-253005 -> 37279234 | AA4: =IF(Z4=0,0,Z4/G4) -> 0.35687662 | AB4: =+'Vtas efectivo'!Z4 -> 2060238 | AC4: =IF(AB4=0,0,AB4/G4) -> 0.019722797 | AE4: =IF(AD4=0,0,AD4/G4) -> 0 | AF4: 277000 | AG4: =IF(AF4=0,0,AF4/G4) -> 0.0026517397 | AH4: =+'Vtas efectivo'!BK4 -> 0 | AI4: =IF(AH4=0,0,AH4/G4) -> 0 | AJ4: 35557000 | AK4: =+J4-AJ4 -> -34813.1 | AL4: =+AL3+AK4 -> -405484.3 | AN4: =+AM4-AJ4 -> -35557000 | AO4: =+AO3+AN4 -> -70648000
B5: 3 | C5: =+Bioacem!C9 -> M | D5: =+'G. Corriente'!E9*'G. Corriente'!$E$4 -> 43791530 | E5: =+Bioacem!E9*Bioacem!$E$4 -> 56862340 | F5: =+'G. Extra'!E9*'G. Extra'!$E$4 -> 6569373.3 | G5: =SUM(C5:F5) -> 1.0722324e+08 | H5: =+Bioacem!E9+'G. Corriente'!E9+'G. Extra'!E9 -> 8430.76 | I5: =690+401+41+62+27+11+9+14+1 -> 1256 | J5: =+G5-L5-P5-T5-V5-R5-X5-Z5-AB5-AD5-AF5-AH5 -> 37613323 | K5: =IF(J5=0,0,J5/G5) -> 0.35079449 | L5: =15346584-N5 -> 15020193 | M5: =IF(L5=0,0,L5/G5) -> 0.14008337 | N5: 326391 | O5: =IF(N5=0,0,N5/G5) -> 0.0030440321 | Q5: =IF(P5=0,0,P5/G5) -> 0 | R5: 6745965 | S5: =IF(R5=0,0,R5/G5) -> 0.062915136 | T5: =4511303+'Vtas efectivo'!BJ5 -> 6214052 | U5: =IF(T5=0,0,T5/G5) -> 0.057954337 | V5: 49128 | W5: =IF(V5=0,0,V5/G5) -> 0.00045818424 | X5: 1330663 | Y5: =IF(X5=0,0,X5/G5) -> 0.01241021 | Z5: =34703935+4281199 -> 38985134 | AA5: =IF(Z5=0,0,Z5/G5) -> 0.36358846 | AB5: =+'Vtas efectivo'!Z5 -> 1100786 | AC5: =IF(AB5=0,0,AB5/G5) -> 0.0102663 | AE5: =IF(AD5=0,0,AD5/G5) -> 0 | AF5: 164000 | AG5: =IF(AF5=0,0,AF5/G5) -> 0.0015295191 | AH5: =+'Vtas efectivo'!BK5 -> 0 | AI5: =IF(AH5=0,0,AH5/G5) -> 0 | AJ5: 37496000 | AK5: =+J5-AJ5 -> 117322.8 | AL5: =+AL4+AK5 -> -288161.5 | AN5: =+AM5-AJ5 -> -37496000 | AO5: =+AO4+AN5 -> -108144000
B6: 4 | C6: =+Bioacem!C10 -> M | D6: =+'G. Corriente'!E10*'G. Corriente'!$E$4 -> 44562144 | E6: =+Bioacem!E10*Bioacem!$E$4 -> 60013487 | F6: =+'G. Extra'!E10*'G. Extra'!$E$4 -> 5939105.7 | G6: =SUM(C6:F6) -> 1.1051474e+08 | H6: =+Bioacem!E10+'G. Corriente'!E10+'G. Extra'!E10 -> 8741.44 | I6: =666+390+34+61+30+15+12+5 -> 1213 | J6: =+G6-L6-P6-T6-V6-R6-X6-Z6-AB6-AD6-AF6-AH6 -> 39396453 | K6: =IF(J6=0,0,J6/G6) -> 0.35648145 | L6: =14277999-N6 -> 14208699 | M6: =IF(L6=0,0,L6/G6) -> 0.12856836 | N6: 69300 | O6: =IF(N6=0,0,N6/G6) -> 0.00062706569 | Q6: =IF(P6=0,0,P6/G6) -> 0 | R6: 5495035 | S6: =IF(R6=0,0,R6/G6) -> 0.049722192 | T6: =6148176+'Vtas efectivo'!BJ6 -> 6438662 | U6: =IF(T6=0,0,T6/G6) -> 0.058260664 | W6: =IF(V6=0,0,V6/G6) -> 0 | X6: 709302 | Y6: =IF(X6=0,0,X6/G6) -> 0.0064181666 | Z6: =40476235+2797189 -> 43273424 | AA6: =IF(Z6=0,0,Z6/G6) -> 0.39156247 | AB6: =+'Vtas efectivo'!Z6 -> 606162 | AC6: =IF(AB6=0,0,AB6/G6) -> 0.0054848974 | AE6: =IF(AD6=0,0,AD6/G6) -> 0 | AF6: 387000 | AG6: =IF(AF6=0,0,AF6/G6) -> 0.0035017954 | AH6: =+'Vtas efectivo'!BK6 -> 0 | AI6: =IF(AH6=0,0,AH6/G6) -> 0 | AJ6: 39207000 | AK6: =+J6-AJ6 -> 189453.4 | AL6: =+AL5+AK6 -> -98708.1 | AN6: =+AM6-AJ6 -> -39207000 | AO6: =+AO5+AN6 -> -147351000
B7: 5 | C7: =+Bioacem!C11 -> J | D7: =+'G. Corriente'!E11*'G. Corriente'!$G$4 -> 21203873 | E7: =+Bioacem!E11*Bioacem!$E$4 -> 60859620 | F7: =+'G. Extra'!E11*'G. Extra'!$E$4 -> 1704371.7 | G7: =SUM(C7:F7) -> 83767865 | H7: =+Bioacem!E11+'G. Corriente'!E11+'G. Extra'!E11 -> 7143.48 | I7: =416+182+22+58+44+5+3+4 -> 734 | J7: =+G7-L7-P7-T7-V7-R7-X7-Z7-AB7-AD7-AF7-AH7 -> 27053983 | K7: =IF(J7=0,0,J7/G7) -> 0.32296374 | L7: =12917658-N7 -> 12561260 | M7: =IF(L7=0,0,L7/G7) -> 0.14995321 | N7: 356398 | O7: =IF(N7=0,0,N7/G7) -> 0.004254591 | Q7: =IF(P7=0,0,P7/G7) -> 0 | R7: 9265958 | S7: =IF(R7=0,0,R7/G7) -> 0.11061471 | T7: =3947788+'Vtas efectivo'!BJ7 -> 5134058 | U7: =IF(T7=0,0,T7/G7) -> 0.061289112 | W7: =IF(V7=0,0,V7/G7) -> 0 | X7: 567228 | Y7: =IF(X7=0,0,X7/G7) -> 0.0067714272 | Z7: =26265813+2317230 -> 28583043 | AA7: =IF(Z7=0,0,Z7/G7) -> 0.34121728 | AB7: =+'Vtas efectivo'!Z7 -> 519335 | AC7: =IF(AB7=0,0,AB7/G7) -> 0.0061996925 | AE7: =IF(AD7=0,0,AD7/G7) -> 0 | AF7: 83000 | AG7: =IF(AF7=0,0,AF7/G7) -> 0.00099083342 | AH7: =+'Vtas efectivo'!BK7 -> 0 | AI7: =IF(AH7=0,0,AH7/G7) -> 0 | AJ7: 26692000 | AK7: =+J7-AJ7 -> 361982.6 | AL7: =+AL6+AK7 -> 263274.5 | AM7: 113099000 | AN7: =+AM7-AJ7 -> 86407000 | AO7: =+AO6+AN7 -> -60944000
B8: 6 | C8: =+Bioacem!C12 -> V | D8: =+'G. Corriente'!E12*'G. Corriente'!$G$4 -> 58436082 | E8: =+Bioacem!E12*Bioacem!$E$4 -> 47770635 | F8: =+'G. Extra'!E12*'G. Extra'!$E$4 -> 6546637.8 | G8: =SUM(C8:F8) -> 1.1275335e+08 | H8: =+Bioacem!E12+'G. Corriente'!E12+'G. Extra'!E12 -> 8621.93 | I8: =824+440+40+29+35+11+53+5 -> 1437 | J8: =+G8-L8-P8-T8-V8-R8-X8-Z8-AB8-AD8-AF8-AH8 -> 38929003 | K8: =IF(J8=0,0,J8/G8) -> 0.34525804 | L8: =9945579-N8 -> 9822371 | M8: =IF(L8=0,0,L8/G8) -> 0.087113781 | N8: 123208 | O8: =IF(N8=0,0,N8/G8) -> 0.0010927214 | Q8: =IF(P8=0,0,P8/G8) -> 0 | R8: 7748215 | S8: =IF(R8=0,0,R8/G8) -> 0.068718266 | T8: =3763063+'Vtas efectivo'!BJ8 -> 5705014 | U8: =IF(T8=0,0,T8/G8) -> 0.050597288 | W8: =IF(V8=0,0,V8/G8) -> 0 | X8: 590211 | Y8: =IF(X8=0,0,X8/G8) -> 0.0052345316 | Z8: =40894071+6636380 -> 47530451 | AA8: =IF(Z8=0,0,Z8/G8) -> 0.42154356 | AB8: =+'Vtas efectivo'!Z8 -> 2088640 | AC8: =IF(AB8=0,0,AB8/G8) -> 0.018523972 | AE8: =IF(AD8=0,0,AD8/G8) -> 0 | AF8: 197000 | AG8: =IF(AF8=0,0,AF8/G8) -> 0.0017471764 | AH8: =+'Vtas efectivo'!BK8 -> 142450 | AI8: =IF(AH8=0,0,AH8/G8) -> 0.001263377 | AJ8: 38799000 | AK8: =+J8-AJ8 -> 130002.7 | AL8: =+AL7+AK8 -> 393277.2 | AM8: 26740000 | AN8: =+AM8-AJ8 -> -12059000 | AO8: =+AO7+AN8 -> -73003000
B9: 7 | C9: =+Bioacem!C13 -> S | D9: =+'G. Corriente'!E13*'G. Corriente'!$G$4 -> 73306180 | E9: =+Bioacem!E13*Bioacem!$E$4 -> 45138820 | F9: =+'G. Extra'!E13*'G. Extra'!$G$4 -> 11897107 | G9: =SUM(C9:F9) -> 1.3034211e+08 | H9: =+Bioacem!E13+'G. Corriente'!E13+'G. Extra'!E13 -> 9683.3 | I9: =755+618+24+33+7+15+14+5+2 -> 1473 | J9: =+G9-L9-P9-T9-V9-R9-X9-Z9-AB9-AD9-AF9-AH9 -> 44718814 | K9: =IF(J9=0,0,J9/G9) -> 0.34308801 | L9: =10384172-N9 -> 10326722 | M9: =IF(L9=0,0,L9/G9) -> 0.079227827 | N9: 57450 | O9: =IF(N9=0,0,N9/G9) -> 0.00044076317 | Q9: =IF(P9=0,0,P9/G9) -> 0 | R9: 3999655 | S9: =IF(R9=0,0,R9/G9) -> 0.030685824 | T9: =1270408+'Vtas efectivo'!BJ9 -> 2736310 | U9: =IF(T9=0,0,T9/G9) -> 0.020993293 | V9: 343754 | W9: =IF(V9=0,0,V9/G9) -> 0.0026373212 | X9: 818085 | Y9: =IF(X9=0,0,X9/G9) -> 0.0062764445 | Z9: =64565637+839652 -> 65405289 | AA9: =IF(Z9=0,0,Z9/G9) -> 0.50179708 | AB9: =+'Vtas efectivo'!Z9 -> 1729379 | AC9: =IF(AB9=0,0,AB9/G9) -> 0.013267999 | AE9: =IF(AD9=0,0,AD9/G9) -> 0 | AF9: 241000 | AG9: =IF(AF9=0,0,AF9/G9) -> 0.0018489804 | AH9: =+'Vtas efectivo'!BK9 -> 23100 | AI9: =IF(AH9=0,0,AH9/G9) -> 0.00017722592 | AJ9: 44699000 | AK9: =+J9-AJ9 -> 19813.8 | AL9: =+AL8+AK9 -> 413091 | AN9: =+AM9-AJ9 -> -44699000 | AO9: =+AO8+AN9 -> -117702000
B10: 8 | C10: =+Bioacem!C14 -> D | D10: =+'G. Corriente'!E14*'G. Corriente'!$G$4 -> 67194940 | E10: =+Bioacem!E14*Bioacem!$E$4 -> 19060072 | F10: =+'G. Extra'!E14*'G. Extra'!$G$4 -> 7463090.7 | G10: =SUM(C10:F10) -> 93718103 | H10: =+Bioacem!E14+'G. Corriente'!E14+'G. Extra'!E14 -> 6609.67 | I10: =686+509+22+14+4+10+2+1 -> 1248 | J10: =+G10-L10-P10-T10-V10-R10-X10-Z10-AB10-AD10-AF10-AH10 -> 35956841 | K10: =IF(J10=0,0,J10/G10) -> 0.38367017 | L10: =4665267-N10 -> 4487389 | M10: =IF(L10=0,0,L10/G10) -> 0.047881774 | N10: 177878 | O10: =IF(N10=0,0,N10/G10) -> 0.0018980111 | Q10: =IF(P10=0,0,P10/G10) -> 0 | R10: 730732 | S10: =IF(R10=0,0,R10/G10) -> 0.0077971275 | T10: =590831+'Vtas efectivo'!BJ10 -> 671241 | U10: =IF(T10=0,0,T10/G10) -> 0.0071623409 | V10: 57008 | W10: =IF(V10=0,0,V10/G10) -> 0.0006082923 | Y10: =IF(X10=0,0,X10/G10) -> 0 | Z10: =45805743+4407877 -> 50213620 | AA10: =IF(Z10=0,0,Z10/G10) -> 0.53579424 | AB10: =+'Vtas efectivo'!Z10 -> 1278272 | AC10: =IF(AB10=0,0,AB10/G10) -> 0.013639542 | AE10: =IF(AD10=0,0,AD10/G10) -> 0 | AF10: 323000 | AG10: =IF(AF10=0,0,AF10/G10) -> 0.003446506 | AH10: =+'Vtas efectivo'!BK10 -> 0 | AI10: =IF(AH10=0,0,AH10/G10) -> 0 | AJ10: 35656000 | AK10: =+J10-AJ10 -> 300840.9 | AL10: =+AL9+AK10 -> 713931.9 | AN10: =+AM10-AJ10 -> -35656000 | AO10: =+AO9+AN10 -> -153358000
B11: 9 | C11: =+Bioacem!C15 -> L | D11: =+'G. Corriente'!E15*'G. Corriente'!$G$4 -> 48895547 | E11: =+Bioacem!E15*Bioacem!$E$4 -> 52803570 | F11: =+'G. Extra'!E15*'G. Extra'!$G$4 -> 5242287.7 | G11: =SUM(C11:F11) -> 1.069414e+08 | H11: =+Bioacem!E15+'G. Corriente'!E15+'G. Extra'!E15 -> 8421 | I11: =701+442+41+62+21+24+12+2 -> 1305 | J11: =+G11-L11-P11-T11-V11-R11-X11-Z11-AB11-AD11-AF11-AH11 -> 39042894 | K11: =IF(J11=0,0,J11/G11) -> 0.36508679 | L11: =10668976-N11 -> 10520959 | M11: =IF(L11=0,0,L11/G11) -> 0.098380595 | N11: 148017 | O11: =IF(N11=0,0,N11/G11) -> 0.0013840944 | Q11: =IF(P11=0,0,P11/G11) -> 0 | R11: 8099551 | S11: =IF(R11=0,0,R11/G11) -> 0.075738214 | T11: =4854763+'Vtas efectivo'!BJ11 -> 6298874 | U11: =IF(T11=0,0,T11/G11) -> 0.058900236 | W11: =IF(V11=0,0,V11/G11) -> 0 | X11: 378443 | Y11: =IF(X11=0,0,X11/G11) -> 0.0035387884 | Z11: =39165663+1133769 -> 40299432 | AA11: =IF(Z11=0,0,Z11/G11) -> 0.37683657 | AB11: =+'Vtas efectivo'!Z11 -> 2061251 | AC11: =IF(AB11=0,0,AB11/G11) -> 0.019274583 | AE11: =IF(AD11=0,0,AD11/G11) -> 0 | AF11: 240000 | AG11: =IF(AF11=0,0,AF11/G11) -> 0.0022442196 | AH11: =+'Vtas efectivo'!BK11 -> 0 | AI11: =IF(AH11=0,0,AH11/G11) -> 0 | AJ11: 39116000 | AK11: =+J11-AJ11 -> -73105.6 | AL11: =+AL10+AK11 -> 640826.3 | AM11: 126512000 | AN11: =+AM11-AJ11 -> 87396000 | AO11: =+AO10+AN11 -> -65962000
B12: 10 | C12: =+Bioacem!C16 -> M | D12: =+'G. Corriente'!E16*'G. Corriente'!$G$4 -> 48712052 | E12: =+Bioacem!E16*Bioacem!$E$4 -> 56242818 | F12: =+'G. Extra'!E16*'G. Extra'!$G$4 -> 5234336.9 | G12: =SUM(C12:F12) -> 1.1018921e+08 | H12: =+Bioacem!E16+'G. Corriente'!E16+'G. Extra'!E16 -> 8728.41 | I12: =665+477+44+32+15+11+55+1+6+1 -> 1307 | J12: =+G12-L12-P12-T12-V12-R12-X12-Z12-AB12-AD12-AF12-AH12 -> 38308780 | K12: =IF(J12=0,0,J12/G12) -> 0.34766364 | L12: =13625822-N12 -> 13333222 | M12: =IF(L12=0,0,L12/G12) -> 0.12100298 | N12: =254100+38500 -> 292600 | O12: =IF(N12=0,0,N12/G12) -> 0.0026554325 | Q12: =IF(P12=0,0,P12/G12) -> 0 | R12: 8789210 | S12: =IF(R12=0,0,R12/G12) -> 0.07976471 | T12: =4960063+'Vtas efectivo'!BJ12 -> 6522444 | U12: =IF(T12=0,0,T12/G12) -> 0.05919313 | V12: 50000 | W12: =IF(V12=0,0,V12/G12) -> 0.00045376495 | X12: 724261 | Y12: =IF(X12=0,0,X12/G12) -> 0.0065728852 | Z12: =40057432+333128 -> 40390560 | AA12: =IF(Z12=0,0,Z12/G12) -> 0.36655641 | AB12: =+'Vtas efectivo'!Z12 -> 1618779 | AC12: =IF(AB12=0,0,AB12/G12) -> 0.014690904 | AE12: =IF(AD12=0,0,AD12/G12) -> 0 | AF12: 271000 | AG12: =IF(AF12=0,0,AF12/G12) -> 0.0024594061 | AH12: =+'Vtas efectivo'!BK12 -> 180950 | AI12: =IF(AH12=0,0,AH12/G12) -> 0.0016421754 | AJ12: 38316000 | AK12: =+J12-AJ12 -> -7220.1 | AL12: =+AL11+AK12 -> 633606.2 | AN12: =+AM12-AJ12 -> -38316000 | AO12: =+AO11+AN12 -> -104278000
B13: 11 | C13: =+Bioacem!C17 -> M | D13: =+'G. Corriente'!E17*'G. Corriente'!$G$4 -> 50413939 | E13: =+Bioacem!E17*Bioacem!$E$4 -> 52734985 | F13: =+'G. Extra'!E17*'G. Extra'!$G$4 -> 5959124.6 | G13: =SUM(C13:F13) -> 1.0910805e+08 | H13: =+Bioacem!E17+'G. Corriente'!E17+'G. Extra'!E17 -> 8554.25 | I13: =761+424+32+48+27+17+5+19 -> 1333 | J13: =+G13-L13-P13-T13-V13-R13-X13-Z13-AB13-AD13-AF13-AH13 -> 41793115 | K13: =IF(J13=0,0,J13/G13) -> 0.38304337 | L13: =10737100-N13 -> 10737100 | M13: =IF(L13=0,0,L13/G13) -> 0.098407955 | O13: =IF(N13=0,0,N13/G13) -> 0 | Q13: =IF(P13=0,0,P13/G13) -> 0 | R13: 6780813 | S13: =IF(R13=0,0,R13/G13) -> 0.062147688 | T13: =4744288+'Vtas efectivo'!BJ13 -> 5913315 | U13: =IF(T13=0,0,T13/G13) -> 0.054196872 | W13: =IF(V13=0,0,V13/G13) -> 0 | X13: 639079 | Y13: =IF(X13=0,0,X13/G13) -> 0.0058573039 | Z13: =40281428+1675239 -> 41956667 | AA13: =IF(Z13=0,0,Z13/G13) -> 0.38454236 | AB13: =+'Vtas efectivo'!Z13 -> 1074960 | AC13: =IF(AB13=0,0,AB13/G13) -> 0.0098522521 | AE13: =IF(AD13=0,0,AD13/G13) -> 0 | AF13: 213000 | AG13: =IF(AF13=0,0,AF13/G13) -> 0.0019521933 | AH13: =+'Vtas efectivo'!BK13 -> 0 | AI13: =IF(AH13=0,0,AH13/G13) -> 0 | AJ13: 41696000 | AK13: =+J13-AJ13 -> 97114.7 | AL13: =+AL12+AK13 -> 730720.9 | AN13: =+AM13-AJ13 -> -41696000 | AO13: =+AO12+AN13 -> -145974000
B14: 12 | C14: =+Bioacem!C18 -> J | D14: =+'G. Corriente'!E18*'G. Corriente'!$G$4 -> 49553274 | E14: =+Bioacem!E18*Bioacem!$E$4 -> 54925835 | F14: =+'G. Extra'!E18*'G. Extra'!$G$4 -> 5475932.8 | G14: =SUM(C14:F14) -> 1.0995504e+08 | H14: =+Bioacem!E18+'G. Corriente'!E18+'G. Extra'!E18 -> 8674.65 | I14: =747+452+40+19+22+26+53+3+1 -> 1363 | J14: =+G14-L14-P14-T14-V14-R14-X14-Z14-AB14-AD14-AF14-AH14 -> 44030848 | K14: =IF(J14=0,0,J14/G14) -> 0.4004441 | L14: =16226184-N14 -> 16048391 | M14: =IF(L14=0,0,L14/G14) -> 0.14595412 | N14: 177793 | O14: =IF(N14=0,0,N14/G14) -> 0.0016169609 | Q14: =IF(P14=0,0,P14/G14) -> 0 | R14: 5490777 | S14: =IF(R14=0,0,R14/G14) -> 0.049936564 | T14: =4482331+'Vtas efectivo'!BJ14 -> 5143479 | U14: =IF(T14=0,0,T14/G14) -> 0.046778019 | V14: 30380 | W14: =IF(V14=0,0,V14/G14) -> 0.00027629474 | X14: 418636 | Y14: =IF(X14=0,0,X14/G14) -> 0.0038073379 | Z14: =38828801-1744507 -> 37084294 | AA14: =IF(Z14=0,0,Z14/G14) -> 0.33726779 | AB14: =+'Vtas efectivo'!Z14 -> 1276237 | AC14: =IF(AB14=0,0,AB14/G14) -> 0.011606898 | AE14: =IF(AD14=0,0,AD14/G14) -> 0 | AF14: 432000 | AG14: =IF(AF14=0,0,AF14/G14) -> 0.0039288785 | AH14: =+'Vtas efectivo'!BK14 -> 0 | AI14: =IF(AH14=0,0,AH14/G14) -> 0 | AJ14: 43608000 | AK14: =+J14-AJ14 -> 422847.5 | AL14: =+AL13+AK14 -> 1153568.4 | AM14: 114715000 | AN14: =+AM14-AJ14 -> 71107000 | AO14: =+AO13+AN14 -> -74867000
B15: 13 | C15: =+Bioacem!C19 -> V | D15: =+'G. Corriente'!E19*'G. Corriente'!$G$4 -> 55689122 | E15: =+Bioacem!E19*Bioacem!$E$4 -> 50430938 | F15: =+'G. Extra'!E19*'G. Extra'!$G$4 -> 8097709.1 | G15: =SUM(C15:F15) -> 1.1421777e+08 | H15: =+Bioacem!E19+'G. Corriente'!E19+'G. Extra'!E19 -> 8805.55 | I15: =716+460+30+56+38+14+6+4 -> 1324 | J15: =+G15-L15-P15-T15-V15-R15-X15-Z15-AB15-AD15-AF15-AH15 -> 36925128 | K15: =IF(J15=0,0,J15/G15) -> 0.32328707 | L15: =14060713-N15 -> 13607841 | M15: =IF(L15=0,0,L15/G15) -> 0.11913944 | N15: 452872 | O15: =IF(N15=0,0,N15/G15) -> 0.0039649873 | Q15: =IF(P15=0,0,P15/G15) -> 0 | R15: 6293578 | S15: =IF(R15=0,0,R15/G15) -> 0.055101567 | T15: =6619940+'Vtas efectivo'!BJ15 -> 7901832 | U15: =IF(T15=0,0,T15/G15) -> 0.06918216 | W15: =IF(V15=0,0,V15/G15) -> 0 | X15: 1007629 | Y15: =IF(X15=0,0,X15/G15) -> 0.0088219986 | Z15: =43735330+3567100 -> 47302430 | AA15: =IF(Z15=0,0,Z15/G15) -> 0.41414248 | AB15: =+'Vtas efectivo'!Z15 -> 957331 | AC15: =IF(AB15=0,0,AB15/G15) -> 0.0083816293 | AE15: =IF(AD15=0,0,AD15/G15) -> 0 | AF15: 222000 | AG15: =IF(AF15=0,0,AF15/G15) -> 0.0019436555 | AH15: =+'Vtas efectivo'!BK15 -> 0 | AI15: =IF(AH15=0,0,AH15/G15) -> 0 | AJ15: 36864000 | AK15: =+J15-AJ15 -> 61127.9 | AL15: =+AL14+AK15 -> 1214696.3 | AM15: 38467000 | AN15: =+AM15-AJ15 -> 1603000 | AO15: =+AO14+AN15 -> -73264000
B16: 14 | C16: =+Bioacem!C20 -> S | D16: =+'G. Corriente'!E20*'G. Corriente'!$G$4 -> 87478906 | E16: =+Bioacem!E20*Bioacem!$E$4 -> 33863468 | F16: =+'G. Extra'!E20*'G. Extra'!$G$4 -> 14508584 | G16: =SUM(C16:F16) -> 1.3585096e+08 | H16: =+Bioacem!E20+'G. Corriente'!E20+'G. Extra'!E20 -> 9711.98 | I16: =810+780+35+17+5+14+8+10 -> 1679 | J16: =+G16-L16-P16-T16-V16-R16-X16-Z16-AB16-AD16-AF16-AH16 -> 43294512 | K16: =IF(J16=0,0,J16/G16) -> 0.31869126 | L16: =11146543-N16 -> 11061843 | M16: =IF(L16=0,0,L16/G16) -> 0.081426316 | N16: 84700 | O16: =IF(N16=0,0,N16/G16) -> 0.00062347739 | Q16: =IF(P16=0,0,P16/G16) -> 0 | R16: 3571815 | S16: =IF(R16=0,0,R16/G16) -> 0.026292159 | T16: =1165343+'Vtas efectivo'!BJ16 -> 1800001 | U16: =IF(T16=0,0,T16/G16) -> 0.013249822 | W16: =IF(V16=0,0,V16/G16) -> 0 | X16: 721426 | Y16: =IF(X16=0,0,X16/G16) -> 0.0053104226 | Z16: =72644960+1228876 -> 73873836 | AA16: =IF(Z16=0,0,Z16/G16) -> 0.54378591 | AB16: =+'Vtas efectivo'!Z16 -> 1378524 | AC16: =IF(AB16=0,0,AB16/G16) -> 0.010147326 | AE16: =IF(AD16=0,0,AD16/G16) -> 0 | AF16: 149000 | AG16: =IF(AF16=0,0,AF16/G16) -> 0.0010967902 | AH16: =+'Vtas efectivo'!BK16 -> 0 | AI16: =IF(AH16=0,0,AH16/G16) -> 0 | AJ16: 42839000 | AK16: =+J16-AJ16 -> 455512.4 | AL16: =+AL15+AK16 -> 1670208.7 | AN16: =+AM16-AJ16 -> -42839000 | AO16: =+AO15+AN16 -> -116103000
B17: 15 | C17: =+Bioacem!C21 -> D | D17: =+'G. Corriente'!E21*'G. Corriente'!$G$4 -> 72727745 | E17: =+Bioacem!E21*Bioacem!$E$4 -> 15621470 | F17: =+'G. Extra'!E21*'G. Extra'!$G$4 -> 8218778.1 | G17: =SUM(C17:F17) -> 96567993 | H17: =+Bioacem!E21+'G. Corriente'!E21+'G. Extra'!E21 -> 6695.86 | I17: =708+550+19+10+8+14+1+1+1 -> 1312 | J17: =+G17-L17-P17-T17-V17-R17-X17-Z17-AB17-AD17-AF17-AH17 -> 39367127 | K17: =IF(J17=0,0,J17/G17) -> 0.40766227 | L17: 2499572 | M17: =IF(L17=0,0,L17/G17) -> 0.025884063 | O17: =IF(N17=0,0,N17/G17) -> 0 | Q17: =IF(P17=0,0,P17/G17) -> 0 | R17: 1431561 | S17: =IF(R17=0,0,R17/G17) -> 0.014824384 | T17: =1101284+'Vtas efectivo'!BJ17 -> 1355253 | U17: =IF(T17=0,0,T17/G17) -> 0.014034184 | V17: 53614 | W17: =IF(V17=0,0,V17/G17) -> 0.00055519431 | X17: 156396 | Y17: =IF(X17=0,0,X17/G17) -> 0.0016195428 | Z17: =49088860+1548153 -> 50637013 | AA17: =IF(Z17=0,0,Z17/G17) -> 0.52436642 | AB17: =+'Vtas efectivo'!Z17 -> 604457 | AC17: =IF(AB17=0,0,AB17/G17) -> 0.0062593928 | AE17: =IF(AD17=0,0,AD17/G17) -> 0 | AF17: 463000 | AG17: =IF(AF17=0,0,AF17/G17) -> 0.0047945492 | AH17: =+'Vtas efectivo'!BK17 -> 0 | AI17: =IF(AH17=0,0,AH17/G17) -> 0 | AJ17: 39299000 | AK17: =+J17-AJ17 -> 68127.4 | AL17: =+AL16+AK17 -> 1738336.1 | AN17: =+AM17-AJ17 -> -39299000 | AO17: =+AO16+AN17 -> -155402000
B18: 16 | C18: =+Bioacem!C22 -> L | D18: =+'G. Corriente'!E22*'G. Corriente'!$G$4 -> 47347838 | E18: =+Bioacem!E22*Bioacem!$E$4 -> 64411635 | F18: =+'G. Extra'!E22*'G. Extra'!$G$4 -> 5419554.4 | G18: =SUM(C18:F18) -> 117179027 | H18: =+Bioacem!E22+'G. Corriente'!E22+'G. Extra'!E22 -> 9408.74 | I18: =753+450+62+41+29+12+8+1+4 -> 1360 | J18: =+G18-L18-P18-T18-V18-R18-X18-Z18-AB18-AD18-AF18-AH18 -> 40884134 | K18: =IF(J18=0,0,J18/G18) -> 0.34890317 | L18: =18563517-N18+29950 -> 18471507 | M18: =IF(L18=0,0,L18/G18) -> 0.15763492 | N18: 121960 | O18: =IF(N18=0,0,N18/G18) -> 0.0010408006 | Q18: =IF(P18=0,0,P18/G18) -> 0 | R18: 7896585 | S18: =IF(R18=0,0,R18/G18) -> 0.067389064 | T18: =4910782+'Vtas efectivo'!BJ18 -> 6289095 | U18: =IF(T18=0,0,T18/G18) -> 0.053670825 | V18: 125667 | W18: =IF(V18=0,0,V18/G18) -> 0.0010724359 | X18: 622758 | Y18: =IF(X18=0,0,X18/G18) -> 0.0053145859 | Z18: =39298646+2239802 -> 41538448 | AA18: =IF(Z18=0,0,Z18/G18) -> 0.35448705 | AB18: =+'Vtas efectivo'!Z18 -> 1234833 | AC18: =IF(AB18=0,0,AB18/G18) -> 0.010538004 | AE18: =IF(AD18=0,0,AD18/G18) -> 0 | AF18: 116000 | AG18: =IF(AF18=0,0,AF18/G18) -> 0.00098993824 | AH18: =+'Vtas efectivo'!BK18 -> 0 | AI18: =IF(AH18=0,0,AH18/G18) -> 0 | AJ18: 40869000 | AK18: =+J18-AJ18 -> 15134 | AL18: =+AL17+AK18 -> 1753470.1 | AM18: 124978000 | AN18: =+AM18-AJ18 -> 84109000 | AO18: =+AO17+AN18 -> -71293000
B19: 17 | C19: =+Bioacem!C23 -> M | D19: =+'G. Corriente'!E23*'G. Corriente'!$G$4 -> 53135683 | E19: =+Bioacem!E23*Bioacem!$E$4 -> 51249872 | F19: =+'G. Extra'!E23*'G. Extra'!$G$4 -> 5758005.5 | G19: =SUM(C19:F19) -> 1.1014356e+08 | H19: =+Bioacem!E23+'G. Corriente'!E23+'G. Extra'!E23 -> 8584.15 | I19: =772+49+478+58+16+32+14+2+2 -> 1423 | J19: =+G19-L19-P19-T19-V19-R19-X19-Z19-AB19-AD19-AF19-AH19 -> 41584171 | K19: =IF(J19=0,0,J19/G19) -> 0.37754519 | L19: =10704802-N19 -> 10481252 | M19: =IF(L19=0,0,L19/G19) -> 0.095159916 | N19: 223550 | O19: =IF(N19=0,0,N19/G19) -> 0.0020296239 | Q19: =IF(P19=0,0,P19/G19) -> 0 | R19: 8078185 | S19: =IF(R19=0,0,R19/G19) -> 0.073342326 | T19: =5580264+'Vtas efectivo'!BJ19 -> 6695453 | U19: =IF(T19=0,0,T19/G19) -> 0.060788419 | V19: 470011 | W19: =IF(V19=0,0,V19/G19) -> 0.0042672581 | X19: 100000 | Y19: =IF(X19=0,0,X19/G19) -> 0.000907906 | Z19: =39370234+1932518 -> 41302752 | AA19: =IF(Z19=0,0,Z19/G19) -> 0.37499016 | AB19: =+'Vtas efectivo'!Z19 -> 1221737 | AC19: =IF(AB19=0,0,AB19/G19) -> 0.011092224 | AE19: =IF(AD19=0,0,AD19/G19) -> 0 | AF19: 210000 | AG19: =IF(AF19=0,0,AF19/G19) -> 0.0019066026 | AH19: =+'Vtas efectivo'!BK19 -> 0 | AI19: =IF(AH19=0,0,AH19/G19) -> 0 | AJ19: 41422000 | AK19: =+J19-AJ19 -> 162171.3 | AL19: =+AL18+AK19 -> 1915641.4 | AN19: =+AM19-AJ19 -> -41422000 | AO19: =+AO18+AN19 -> -112715000
B20: 18 | C20: =+Bioacem!C24 -> M | D20: =+'G. Corriente'!E24*'G. Corriente'!$G$4 -> 51048122 | E20: =+Bioacem!E24*Bioacem!$E$4 -> 55509775 | F20: =+'G. Extra'!E24*'G. Extra'!$G$4 -> 5105497.8 | G20: =SUM(C20:F20) -> 1.1166339e+08 | H20: =+Bioacem!E24+'G. Corriente'!E24+'G. Extra'!E24 -> 8806.88 | I20: =758+449+42+56+20+5+33+7 -> 1370 | J20: =+G20-L20-P20-T20-V20-R20-X20-Z20-AB20-AD20-AF20-AH20 -> 36961326 | K20: =IF(J20=0,0,J20/G20) -> 0.33100665 | L20: =14461260-N20 -> 14107915 | M20: =IF(L20=0,0,L20/G20) -> 0.12634324 | N20: 353345 | O20: =IF(N20=0,0,N20/G20) -> 0.0031643763 | Q20: =IF(P20=0,0,P20/G20) -> 0 | R20: 7960980 | S20: =IF(R20=0,0,R20/G20) -> 0.071294447 | T20: =6302169+'Vtas efectivo'!BJ20 -> 6888035 | U20: =IF(T20=0,0,T20/G20) -> 0.061685703 | W20: =IF(V20=0,0,V20/G20) -> 0 | X20: 931755 | Y20: =IF(X20=0,0,X20/G20) -> 0.0083443191 | Z20: =39142824+3077715 -> 42220539 | AA20: =IF(Z20=0,0,Z20/G20) -> 0.37810546 | AB20: =+'Vtas efectivo'!Z20 -> 2343044 | AC20: =IF(AB20=0,0,AB20/G20) -> 0.020983098 | AE20: =IF(AD20=0,0,AD20/G20) -> 0 | AF20: 142000 | AG20: =IF(AF20=0,0,AF20/G20) -> 0.0012716791 | AH20: =+'Vtas efectivo'!BK20 -> 107800 | AI20: =IF(AH20=0,0,AH20/G20) -> 0.00096540142 | AJ20: 36773000 | AK20: =+J20-AJ20 -> 188326.4 | AL20: =+AL19+AK20 -> 2103967.8 | AN20: =+AM20-AJ20 -> -36773000 | AO20: =+AO19+AN20 -> -149488000
B21: 19 | C21: =+Bioacem!C25 -> J | D21: =+'G. Corriente'!E25*'G. Corriente'!$G$4 -> 52638515 | E21: =+Bioacem!E25*Bioacem!$E$4 -> 51555172 | F21: =+'G. Extra'!E25*'G. Extra'!$G$4 -> 6145607 | G21: =SUM(C21:F21) -> 1.1033929e+08 | H21: =+Bioacem!E25+'G. Corriente'!E25+'G. Extra'!E25 -> 8601.27 | I21: =707+442+27+47+24+58+3+21+1 -> 1330 | J21: =+G21-L21-P21-T21-V21-R21-X21-Z21-AB21-AD21-AF21-AH21 -> 37332189 | K21: =IF(J21=0,0,J21/G21) -> 0.33833993 | L21: =14794561-N21 -> 14756723 | M21: =IF(L21=0,0,L21/G21) -> 0.13373951 | N21: 37838 | O21: =IF(N21=0,0,N21/G21) -> 0.00034292407 | Q21: =IF(P21=0,0,P21/G21) -> 0 | R21: 7376378 | S21: =IF(R21=0,0,R21/G21) -> 0.066851778 | T21: =4315529+'Vtas efectivo'!BJ21 -> 4686438 | U21: =IF(T21=0,0,T21/G21) -> 0.042472974 | V21: 159000 | W21: =IF(V21=0,0,V21/G21) -> 0.0014410098 | X21: 627249 | Y21: =IF(X21=0,0,X21/G21) -> 0.0056847291 | Z21: =41428002+2097307 -> 43525309 | AA21: =IF(Z21=0,0,Z21/G21) -> 0.39446789 | AB21: =+'Vtas efectivo'!Z21 -> 1546008 | AC21: =IF(AB21=0,0,AB21/G21) -> 0.0140114 | AE21: =IF(AD21=0,0,AD21/G21) -> 0 | AF21: 330000 | AG21: =IF(AF21=0,0,AF21/G21) -> 0.002990775 | AH21: =+'Vtas efectivo'!BK21 -> 0 | AI21: =IF(AH21=0,0,AH21/G21) -> 0 | AJ21: 37212000 | AK21: =+J21-AJ21 -> 120189.1 | AL21: =+AL20+AK21 -> 2224156.9 | AM21: 117573000 | AN21: =+AM21-AJ21 -> 80361000 | AO21: =+AO20+AN21 -> -69127000
B22: 20 | C22: =+Bioacem!C26 -> V | D22: =+'G. Corriente'!E26*'G. Corriente'!$G$4 -> 63973444 | E22: =+Bioacem!E26*Bioacem!$E$4 -> 56111130 | F22: =+'G. Extra'!E26*'G. Extra'!$G$4 -> 8168724.2 | G22: =SUM(C22:F22) -> 1.282533e+08 | H22: =+Bioacem!E26+'G. Corriente'!E26+'G. Extra'!E26 -> 9883.25 | I22: =829+500+25+39+53+27+14+4+1 -> 1492 | J22: =+G22-L22-P22-T22-V22-R22-X22-Z22-AB22-AD22-AF22-AH22 -> 47443550 | K22: =IF(J22=0,0,J22/G22) -> 0.3699207 | L22: =15020059-N22 -> 14923809 | M22: =IF(L22=0,0,L22/G22) -> 0.11636199 | N22: 96250 | O22: =IF(N22=0,0,N22/G22) -> 0.00075046803 | Q22: =IF(P22=0,0,P22/G22) -> 0 | R22: 6068321 | S22: =IF(R22=0,0,R22/G22) -> 0.047315126 | T22: =3466410+'Vtas efectivo'!BJ22 -> 5559122 | U22: =IF(T22=0,0,T22/G22) -> 0.043344866 | V22: 53362 | W22: =IF(V22=0,0,V22/G22) -> 0.00041606727 | X22: 526586 | Y22: =IF(X22=0,0,X22/G22) -> 0.0041058281 | Z22: =47609227+4017539 -> 51626766 | AA22: =IF(Z22=0,0,Z22/G22) -> 0.40253753 | AB22: =+'Vtas efectivo'!Z22 -> 1726783 | AC22: =IF(AB22=0,0,AB22/G22) -> 0.013463849 | AE22: =IF(AD22=0,0,AD22/G22) -> 0 | AF22: 325000 | AG22: =IF(AF22=0,0,AF22/G22) -> 0.0025340479 | AH22: =+'Vtas efectivo'!BK22 -> 0 | AI22: =IF(AH22=0,0,AH22/G22) -> 0 | AJ22: 47271000 | AK22: =+J22-AJ22 -> 172549.7 | AL22: =+AL21+AK22 -> 2396706.6 | AM22: 33496000 | AN22: =+AM22-AJ22 -> -13775000 | AO22: =+AO21+AN22 -> -82902000
B23: 21 | C23: =+Bioacem!C27 -> S | D23: =+'G. Corriente'!E27*'G. Corriente'!$G$4 -> 81926202 | E23: =+Bioacem!E27*Bioacem!$E$4 -> 32103800 | F23: =+'G. Extra'!E27*'G. Extra'!$G$4 -> 13641404 | G23: =SUM(C23:F23) -> 1.2767141e+08 | H23: =+Bioacem!E27+'G. Corriente'!E27+'G. Extra'!E27 -> 9134.75 | I23: =875+707+13+25+10+18+2+3+13+3 -> 1669 | J23: =+G23-L23-P23-T23-V23-R23-X23-Z23-AB23-AD23-AF23-AH23 -> 46151452 | K23: =IF(J23=0,0,J23/G23) -> 0.36148621 | L23: =7217375-N23 -> 7155775 | M23: =IF(L23=0,0,L23/G23) -> 0.056048376 | N23: 61600 | O23: =IF(N23=0,0,N23/G23) -> 0.00048248862 | Q23: =IF(P23=0,0,P23/G23) -> 0 | R23: 2826430 | S23: =IF(R23=0,0,R23/G23) -> 0.022138317 | T23: =1872042+'Vtas efectivo'!BJ23 -> 2256236 | U23: =IF(T23=0,0,T23/G23) -> 0.017672211 | V23: 339759 | W23: =IF(V23=0,0,V23/G23) -> 0.0026611989 | X23: 472261 | Y23: =IF(X23=0,0,X23/G23) -> 0.003699035 | Z23: =63528381+3735732 -> 67264113 | AA23: =IF(Z23=0,0,Z23/G23) -> 0.52685339 | AB23: =+'Vtas efectivo'!Z23 -> 830380 | AC23: =IF(AB23=0,0,AB23/G23) -> 0.0065040405 | AE23: =IF(AD23=0,0,AD23/G23) -> 0 | AF23: 375000 | AG23: =IF(AF23=0,0,AF23/G23) -> 0.0029372278 | AH23: =+'Vtas efectivo'!BK23 -> 0 | AI23: =IF(AH23=0,0,AH23/G23) -> 0 | AJ23: 46067000 | AK23: =+J23-AJ23 -> 84452.1 | AL23: =+AL22+AK23 -> 2481158.7 | AN23: =+AM23-AJ23 -> -46067000 | AO23: =+AO22+AN23 -> -128969000
B24: 22 | C24: =+Bioacem!C28 -> D | D24: =+'G. Corriente'!E28*'G. Corriente'!$G$4 -> 64132332 | E24: =+Bioacem!E28*Bioacem!$E$4 -> 15291660 | F24: =+'G. Extra'!E28*'G. Extra'!$G$4 -> 11045288 | G24: =SUM(C24:F24) -> 90469279 | H24: =+Bioacem!E28+'G. Corriente'!E28+'G. Extra'!E28 -> 6255.74 | I24: =678+516+8+20+2+12+10+1 -> 1247 | J24: =+G24-L24-P24-T24-V24-R24-X24-Z24-AB24-AD24-AF24-AH24 -> 35478399 | K24: =IF(J24=0,0,J24/G24) -> 0.39215963 | L24: =2803839-N24 -> 2767329 | M24: =IF(L24=0,0,L24/G24) -> 0.030588604 | N24: 36510 | O24: =IF(N24=0,0,N24/G24) -> 0.00040356241 | Q24: =IF(P24=0,0,P24/G24) -> 0 | R24: 3197049 | S24: =IF(R24=0,0,R24/G24) -> 0.035338504 | T24: =+'Vtas efectivo'!BJ24 -> 166331 | U24: =IF(T24=0,0,T24/G24) -> 0.0018385357 | V24: 184676 | W24: =IF(V24=0,0,V24/G24) -> 0.0020413117 | Y24: =IF(X24=0,0,X24/G24) -> 0 | Z24: =45437466+2555752 -> 47993218 | AA24: =IF(Z24=0,0,Z24/G24) -> 0.53049188 | AB24: =+'Vtas efectivo'!Z24 -> 346277 | AC24: =IF(AB24=0,0,AB24/G24) -> 0.0038275645 | AE24: =IF(AD24=0,0,AD24/G24) -> 0 | AF24: 336000 | AG24: =IF(AF24=0,0,AF24/G24) -> 0.0037139679 | AH24: =+'Vtas efectivo'!BK24 -> 0 | AI24: =IF(AH24=0,0,AH24/G24) -> 0 | AJ24: 35499000 | AK24: =+J24-AJ24 -> -20600.6 | AL24: =+AL23+AK24 -> 2460558.1 | AN24: =+AM24-AJ24 -> -35499000 | AO24: =+AO23+AN24 -> -164468000
B25: 23 | C25: =+Bioacem!C29 -> L | D25: =+'G. Corriente'!E29*'G. Corriente'!$G$4 -> 50196570 | E25: =+Bioacem!E29*Bioacem!$E$4 -> 56028892 | F25: =+'G. Extra'!E29*'G. Extra'!$G$4 -> 6405815 | G25: =SUM(C25:F25) -> 1.1263128e+08 | H25: =+Bioacem!E29+'G. Corriente'!E29+'G. Extra'!E29 -> 8871.07 | I25: =756+433+44+30+62+8+4+12+2+1 -> 1352 | J25: =+G25-L25-P25-T25-V25-R25-X25-Z25-AB25-AD25-AF25-AH25 -> 45243550 | K25: =IF(J25=0,0,J25/G25) -> 0.40169614 | L25: =12857685+N25 -> 12857685 | M25: =IF(L25=0,0,L25/G25) -> 0.11415732 | O25: =IF(N25=0,0,N25/G25) -> 0 | Q25: =IF(P25=0,0,P25/G25) -> 0 | R25: =7134610+79003 -> 7213613 | S25: =IF(R25=0,0,R25/G25) -> 0.064046268 | T25: =5546456+'Vtas efectivo'!BJ25 -> 5817861 | U25: =IF(T25=0,0,T25/G25) -> 0.051654044 | W25: =IF(V25=0,0,V25/G25) -> 0 | X25: 532290 | Y25: =IF(X25=0,0,X25/G25) -> 0.0047259519 | Z25: =39556343-769035 -> 38787308 | AA25: =IF(Z25=0,0,Z25/G25) -> 0.34437422 | AB25: =+'Vtas efectivo'!Z25 -> 1975971 | AC25: =IF(AB25=0,0,AB25/G25) -> 0.017543715 | AE25: =IF(AD25=0,0,AD25/G25) -> 0 | AF25: 203000 | AG25: =IF(AF25=0,0,AF25/G25) -> 0.0018023413 | AH25: =+'Vtas efectivo'!BK25 -> 0 | AI25: =IF(AH25=0,0,AH25/G25) -> 0 | AJ25: 45153000 | AK25: =+J25-AJ25 -> 90549.7 | AL25: =+AL24+AK25 -> 2551107.8 | AM25: 121884000 | AN25: =+AM25-AJ25 -> 76731000 | AO25: =+AO24+AN25 -> -87737000
B26: 24 | C26: =+Bioacem!C30 -> M | D26: =+'G. Corriente'!E30*'G. Corriente'!$G$4 -> 48361162 | E26: =+Bioacem!E30*Bioacem!$E$4 -> 53639597 | F26: =+'G. Extra'!E30*'G. Extra'!$G$4 -> 5177416.4 | G26: =SUM(C26:F26) -> 1.0717818e+08 | H26: =+Bioacem!E30+'G. Corriente'!E30+'G. Extra'!E30 -> 8460 | I26: =747+427+50+48+19+24+8+1+2+3 -> 1329 | J26: =+G26-L26-P26-T26-V26-R26-X26-Z26-AB26-AD26-AF26-AH26 -> 37823715 | K26: =IF(J26=0,0,J26/G26) -> 0.35290501 | L26: =12991088-N26 -> 12666575 | M26: =IF(L26=0,0,L26/G26) -> 0.11818241 | N26: 324513 | O26: =IF(N26=0,0,N26/G26) -> 0.0030277899 | Q26: =IF(P26=0,0,P26/G26) -> 0 | R26: 9730177 | S26: =IF(R26=0,0,R26/G26) -> 0.090785058 | T26: =4747126+'Vtas efectivo'!BJ26 -> 6188609 | U26: =IF(T26=0,0,T26/G26) -> 0.057741316 | V26: 337733 | W26: =IF(V26=0,0,V26/G26) -> 0.0031511359 | X26: 375181 | Y26: =IF(X26=0,0,X26/G26) -> 0.0035005354 | Z26: =37238998+702186 -> 37941184 | AA26: =IF(Z26=0,0,Z26/G26) -> 0.35400102 | AB26: =+'Vtas efectivo'!Z26 -> 1993002 | AC26: =IF(AB26=0,0,AB26/G26) -> 0.018595222 | AE26: =IF(AD26=0,0,AD26/G26) -> 0 | AF26: 122000 | AG26: =IF(AF26=0,0,AF26/G26) -> 0.0011382914 | AH26: =+'Vtas efectivo'!BK26 -> 0 | AI26: =IF(AH26=0,0,AH26/G26) -> 0 | AJ26: 37748000 | AK26: =+J26-AJ26 -> 75715.4 | AL26: =+AL25+AK26 -> 2626823.2 | AN26: =+AM26-AJ26 -> -37748000 | AO26: =+AO25+AN26 -> -125485000
B27: 25 | C27: =+Bioacem!C31 -> M | D27: =+'G. Corriente'!E31*'G. Corriente'!$G$4 -> 52674059 | E27: =+Bioacem!E31*Bioacem!$E$4 -> 59307858 | F27: =+'G. Extra'!E31*'G. Extra'!$G$4 -> 6114165.2 | G27: =SUM(C27:F27) -> 1.1809608e+08 | H27: =+Bioacem!E31+'G. Corriente'!E31+'G. Extra'!E31 -> 9323.05 | I27: =811+504+39+31+57+15+2+14+1 -> 1474 | J27: =+G27-L27-P27-T27-V27-R27-X27-Z27-AB27-AD27-AF27-AH27 -> 43240453 | K27: =IF(J27=0,0,J27/G27) -> 0.36614638 | L27: =14231794-N27 -> 14181744 | M27: =IF(L27=0,0,L27/G27) -> 0.12008649 | N27: 50050 | O27: =IF(N27=0,0,N27/G27) -> 0.00042380746 | Q27: =IF(P27=0,0,P27/G27) -> 0 | R27: 7290298 | S27: =IF(R27=0,0,R27/G27) -> 0.061731921 | T27: =6122993+'Vtas efectivo'!BJ27 -> 6512756 | U27: =IF(T27=0,0,T27/G27) -> 0.055147943 | W27: =IF(V27=0,0,V27/G27) -> 0 | X27: 307686 | Y27: =IF(X27=0,0,X27/G27) -> 0.002605387 | Z27: =44171403+1514885 -> 45686288 | AA27: =IF(Z27=0,0,Z27/G27) -> 0.38685693 | AB27: =+'Vtas efectivo'!Z27 -> 460557 | AC27: =IF(AB27=0,0,AB27/G27) -> 0.00389985 | AE27: =IF(AD27=0,0,AD27/G27) -> 0 | AF27: 347000 | AG27: =IF(AF27=0,0,AF27/G27) -> 0.0029382855 | AH27: =+'Vtas efectivo'!BK27 -> 69300 | AI27: =IF(AH27=0,0,AH27/G27) -> 0.00058681032 | AJ27: 42899000 | AK27: =+J27-AJ27 -> 341452.9 | AL27: =+AL26+AK27 -> 2968276.1 | AN27: =+AM27-AJ27 -> -42899000 | AO27: =+AO26+AN27 -> -168384000
